Workbook
Name Slicer_Built: #N/A
Name Slicer_Retired: #N/A

Sheet Dashboard
B2: 🧱 LEGO Collection Dashboard
B4: TOTAL SETS | D4: BUILT | F4: TO BUILD | H4: NOT RETIRED | J4: RETIRED
B5: =COUNTA(Inventory!C2:C1000) -> 138 | D5: =COUNTIF(Inventory!H2:H1000,"YES") -> 66 | F5: =COUNTIF(Inventory!H2:H1000,"NO") -> 72 | H5: =COUNTIF(Inventory!I2:I1000,"Not Retired") -> 75 | J5: =COUNTIF(Inventory!I2:I1000,"Retired") -> 63
B6: =SUMIF(Inventory!E2:E1000,"<>"&"",Inventory!E2:E1000) -> 181466 | D6: =SUMIF(Inventory!H2:H1000,"YES",Inventory!E2:E1000) -> 76040 | F6: =SUMIF(Inventory!H2:H1000,"NO",Inventory!E2:E1000) -> 105426 | H6: =SUMIFS(Inventory!E2:E1000,Inventory!I2:I1000,"Not Retired") -> 114690 | J6: =SUMIFS(Inventory!E2:E1000,Inventory!I2:I1000,"Retired") -> 66776
B7: total bricks owned | D7: bricks assembled | F7: bricks still boxes | H7: bricks still in production | J7: bricks from retired sets
B10: BUILD PROGRESS BY THEME
C11: Built | E11: To Build | G11: Total | I11: Built % | L11: Not Retired | N11: Retired
C12: Sets | D12: Bricks | E12: Sets | F12: Bricks | G12: Sets | H12: Bricks | I12: % Sets | J12: % Bricks | L12: Sets | M12: Bricks | N12: Sets | O12: Bricks
B13: Star Wars | C13: =COUNTIFS(Inventory!D2:D1000,B13,Inventory!H2:H1000,"YES") -> 18 | D13: =SUMIFS(Inventory!E2:E1000,Inventory!D2:D1000,B13,Inventory!H2:H1000,"YES") -> 12974 | E13: =COUNTIFS(Inventory!D2:D1000,B13,Inventory!H2:H1000,"NO") -> 30 | F13: =SUMIFS(Inventory!E2:E1000,Inventory!D2:D1000,B13,Inventory!H2:H1000,"NO") -> 32809 | G13: =C13+E13 -> 48 | H13: =D13+F13 -> 45783 | I13: =IF(G13=0,"",C13/G13) -> 0.375 | J13: =IF(H13=0,"",D13/H13) -> 0.28338029 | L13: =COUNTIFS(Inventory!D2:D1000,B13,Inventory!I2:I1000,"Not Retired") -> 20 | M13: =SUMIFS(Inventory!E2:E1000,Inventory!D2:D1000,B13,Inventory!I2:I1000,"Not Retired") -> 24838 | N13: =COUNTIFS(Inventory!D2:D1000,B13,Inventory!I2:I1000,"Retired") -> 28 | O13: =SUMIFS(Inventory!E2:E1000,Inventory!D2:D1000,B13,Inventory!I2:I1000,"Retired") -> 20945
B14: Architecture | C14: =COUNTIFS(Inventory!D2:D1000,B14,Inventory!H2:H1000,"YES") -> 14 | D14: =SUMIFS(Inventory!E2:E1000,Inventory!D2:D1000,B14,Inventory!H2:H1000,"YES") -> 7272 | E14: =COUNTIFS(Inventory!D2:D1000,B14,Inventory!H2:H1000,"NO") -> 8 | F14: =SUMIFS(Inventory!E2:E1000,Inventory!D2:D1000,B14,Inventory!H2:H1000,"NO") -> 15014 | G14: =C14+E14 -> 22 | H14: =D14+F14 -> 22286 | I14: =IF(G14=0,"",C14/G14) -> 0.63636364 | J14: =IF(H14=0,"",D14/H14) -> 0.32630351 | L14: =COUNTIFS(Inventory!D2:D1000,B14,Inventory!I2:I1000,"Not Retired") -> 7 | M14: =SUMIFS(Inventory!E2:E1000,Inventory!D2:D1000,B14,Inventory!I2:I1000,"Not Retired") -> 15472 | N14: =COUNTIFS(Inventory!D2:D1000,B14,Inventory!I2:I1000,"Retired") -> 15 | O14: =SUMIFS(Inventory!E2:E1000,Inventory!D2:D1000,B14,Inventory!I2:I1000,"Retired") -> 6814
B15: Icons | C15: =COUNTIFS(Inventory!D2:D1000,B15,Inventory!H2:H1000,"YES") -> 8 | D15: =SUMIFS(Inventory!E2:E1000,Inventory!D2:D1000,B15,Inventory!H2:H1000,"YES") -> 18844 | E15: =COUNTIFS(Inventory!D2:D1000,B15,Inventory!H2:H1000,"NO") -> 8 | F15: =SUMIFS(Inventory!E2:E1000,Inventory!D2:D1000,B15,Inventory!H2:H1000,"NO") -> 22865 | G15: =C15+E15 -> 16 | H15: =D15+F15 -> 41709 | I15: =IF(G15=0,"",C15/G15) -> 0.5 | J15: =IF(H15=0,"",D15/H15) -> 0.45179697 | L15: =COUNTIFS(Inventory!D2:D1000,B15,Inventory!I2:I1000,"Not Retired") -> 13 | M15: =SUMIFS(Inventory!E2:E1000,Inventory!D2:D1000,B15,Inventory!I2:I1000,"Not Retired") -> 34793 | N15: =COUNTIFS(Inventory!D2:D1000,B15,Inventory!I2:I1000,"Retired") -> 3 | O15: =SUMIFS(Inventory!E2:E1000,Inventory!D2:D1000,B15,Inventory!I2:I1000,"Retired") -> 6916
B16: Ideas | C16: =COUNTIFS(Inventory!D2:D1000,B16,Inventory!H2:H1000,"YES") -> 6 | D16: =SUMIFS(Inventory!E2:E1000,Inventory!D2:D1000,B16,Inventory!H2:H1000,"YES") -> 8258 | E16: =COUNTIFS(Inventory!D2:D1000,B16,Inventory!H2:H1000,"NO") -> 2 | F16: =SUMIFS(Inventory!E2:E1000,Inventory!D2:D1000,B16,Inventory!H2:H1000,"NO") -> 2880 | G16: =C16+E16 -> 8 | H16: =D16+F16 -> 11138 | I16: =IF(G16=0,"",C16/G16) -> 0.75 | J16: =IF(H16=0,"",D16/H16) -> 0.74142575 | L16: =COUNTIFS(Inventory!D2:D1000,B16,Inventory!I2:I1000,"Not Retired") -> 4 | M16: =SUMIFS(Inventory!E2:E1000,Inventory!D2:D1000,B16,Inventory!I2:I1000,"Not Retired") -> 5203 | N16: =COUNTIFS(Inventory!D2:D1000,B16,Inventory!I2:I1000,"Retired") -> 4 | O16: =SUMIFS(Inventory!E2:E1000,Inventory!D2:D1000,B16,Inventory!I2:I1000,"Retired") -> 5935
B17: Speed Champions | C17: =COUNTIFS(Inventory!D2:D1000,B17,Inventory!H2:H1000,"YES") -> 4 | D17: =SUMIFS(Inventory!E2:E1000,Inventory!D2:D1000,B17,Inventory!H2:H1000,"YES") -> 1259 | E17: =COUNTIFS(Inventory!D2:D1000,B17,Inventory!H2:H1000,"NO") -> 5 | F17: =SUMIFS(Inventory!E2:E1000,Inventory!D2:D1000,B17,Inventory!H2:H1000,"NO") -> 1565 | G17: =C17+E17 -> 9 | H17: =D17+F17 -> 2824 | I17: =IF(G17=0,"",C17/G17) -> 0.44444444 | J17: =IF(H17=0,"",D17/H17) -> 0.44582153 | L17: =COUNTIFS(Inventory!D2:D1000,B17,Inventory!I2:I1000,"Not Retired") -> 8 | M17: =SUMIFS(Inventory!E2:E1000,Inventory!D2:D1000,B17,Inventory!I2:I1000,"Not Retired") -> 2260 | N17: =COUNTIFS(Inventory!D2:D1000,B17,Inventory!I2:I1000,"Retired") -> 1 | O17: =SUMIFS(Inventory!E2:E1000,Inventory!D2:D1000,B17,Inventory!I2:I1000,"Retired") -> 564
B18: Super Mario | C18: =COUNTIFS(Inventory!D2:D1000,B18,Inventory!H2:H1000,"YES") -> 3 | D18: =SUMIFS(Inventory!E2:E1000,Inventory!D2:D1000,B18,Inventory!H2:H1000,"YES") -> 2627 | E18: =COUNTIFS(Inventory!D2:D1000,B18,Inventory!H2:H1000,"NO") -> 4 | F18: =SUMIFS(Inventory!E2:E1000,Inventory!D2:D1000,B18,Inventory!H2:H1000,"NO") -> 8227 | G18: =C18+E18 -> 7 | H18: =D18+F18 -> 10854 | I18: =IF(G18=0,"",C18/G18) -> 0.42857143 | J18: =IF(H18=0,"",D18/H18) -> 0.24203059 | L18: =COUNTIFS(Inventory!D2:D1000,B18,Inventory!I2:I1000,"Not Retired") -> 4 | M18: =SUMIFS(Inventory!E2:E1000,Inventory!D2:D1000,B18,Inventory!I2:I1000,"Not Retired") -> 5167 | N18: =COUNTIFS(Inventory!D2:D1000,B18,Inventory!I2:I1000,"Retired") -> 3 | O18: =SUMIFS(Inventory!E2:E1000,Inventory!D2:D1000,B18,Inventory!I2:I1000,"Retired") -> 5687
B19: Marvel | C19: =COUNTIFS(Inventory!D2:D1000,B19,Inventory!H2:H1000,"YES") -> 1 | D19: =SUMIFS(Inventory!E2:E1000,Inventory!D2:D1000,B19,Inventory!H2:H1000,"YES") -> 436 | E19: =COUNTIFS(Inventory!D2:D1000,B19,Inventory!H2:H1000,"NO") -> 3 | F19: =SUMIFS(Inventory!E2:E1000,Inventory!D2:D1000,B19,Inventory!H2:H1000,"NO") -> 5912 | G19: =C19+E19 -> 4 | H19: =D19+F19 -> 6348 | I19: =IF(G19=0,"",C19/G19) -> 0.25 | J19: =IF(H19=0,"",D19/H19) -> 0.06868305 | L19: =COUNTIFS(Inventory!D2:D1000,B19,Inventory!I2:I1000,"Not Retired") -> 2 | M19: =SUMIFS(Inventory!E2:E1000,Inventory!D2:D1000,B19,Inventory!I2:I1000,"Not Retired") -> 1733 | N19: =COUNTIFS(Inventory!D2:D1000,B19,Inventory!I2:I1000,"Retired") -> 2 | O19: =SUMIFS(Inventory!E2:E1000,Inventory!D2:D1000,B19,Inventory!I2:I1000,"Retired") -> 4615
B20: Creator Expert | C20: =COUNTIFS(Inventory!D2:D1000,B20,Inventory!H2:H1000,"YES") -> 3 | D20: =SUMIFS(Inventory!E2:E1000,Inventory!D2:D1000,B20,Inventory!H2:H1000,"YES") -> 11439 | E20: =COUNTIFS(Inventory!D2:D1000,B20,Inventory!H2:H1000,"NO") -> 0 | F20: =SUMIFS(Inventory!E2:E1000,Inventory!D2:D1000,B20,Inventory!H2:H1000,"NO") -> 0 | G20: =C20+E20 -> 3 | H20: =D20+F20 -> 11439 | I20: =IF(G20=0,"",C20/G20) -> 1 | J20: =IF(H20=0,"",D20/H20) -> 1 | L20: =COUNTIFS(Inventory!D2:D1000,B20,Inventory!I2:I1000,"Not Retired") -> 0 | M20: =SUMIFS(Inventory!E2:E1000,Inventory!D2:D1000,B20,Inventory!I2:I1000,"Not Retired") -> 0 | N20: =COUNTIFS(Inventory!D2:D1000,B20,Inventory!I2:I1000,"Retired") -> 3 | O20: =SUMIFS(Inventory!E2:E1000,Inventory!D2:D1000,B20,Inventory!I2:I1000,"Retired") -> 11439
B21: Technic | C21: =COUNTIFS(Inventory!D2:D1000,B21,Inventory!H2:H1000,"YES") -> 2 | D21: =SUMIFS(Inventory!E2:E1000,Inventory!D2:D1000,B21,Inventory!H2:H1000,"YES") -> 3036 | E21: =COUNTIFS(Inventory!D2:D1000,B21,Inventory!H2:H1000,"NO") -> 0 | F21: =SUMIFS(Inventory!E2:E1000,Inventory!D2:D1000,B21,Inventory!H2:H1000,"NO") -> 0 | G21: =C21+E21 -> 2 | H21: =D21+F21 -> 3036 | I21: =IF(G21=0,"",C21/G21) -> 1 | J21: =IF(H21=0,"",D21/H21) -> 1 | L21: =COUNTIFS(Inventory!D2:D1000,B21,Inventory!I2:I1000,"Not Retired") -> 0 | M21: =SUMIFS(Inventory!E2:E1000,Inventory!D2:D1000,B21,Inventory!I2:I1000,"Not Retired") -> 0 | N21: =COUNTIFS(Inventory!D2:D1000,B21,Inventory!I2:I1000,"Retired") -> 2 | O21: =SUMIFS(Inventory!E2:E1000,Inventory!D2:D1000,B21,Inventory!I2:I1000,"Retired") -> 3036
B22: Editions | C22: =COUNTIFS(Inventory!D2:D1000,B22,Inventory!H2:H1000,"YES") -> 3 | D22: =SUMIFS(Inventory!E2:E1000,Inventory!D2:D1000,B22,Inventory!H2:H1000,"YES") -> 5224 | E22: =COUNTIFS(Inventory!D2:D1000,B22,Inventory!H2:H1000,"NO") -> 4 | F22: =SUMIFS(Inventory!E2:E1000,Inventory!D2:D1000,B22,Inventory!H2:H1000,"NO") -> 3972 | G22: =C22+E22 -> 7 | H22: =D22+F22 -> 9196 | I22: =IF(G22=0,"",C22/G22) -> 0.42857143 | J22: =IF(H22=0,"",D22/H22) -> 0.56807308 | L22: =COUNTIFS(Inventory!D2:D1000,B22,Inventory!I2:I1000,"Not Retired") -> 7 | M22: =SUMIFS(Inventory!E2:E1000,Inventory!D2:D1000,B22,Inventory!I2:I1000,"Not Retired") -> 9196 | N22: =COUNTIFS(Inventory!D2:D1000,B22,Inventory!I2:I1000,"Retired") -> 0 | O22: =SUMIFS(Inventory!E2:E1000,Inventory!D2:D1000,B22,Inventory!I2:I1000,"Retired") -> 0
B23: Other | C23: =COUNTIFS(Inventory!D2:D1000,B23,Inventory!H2:H1000,"YES") -> 1 | D23: =SUMIFS(Inventory!E2:E1000,Inventory!D2:D1000,B23,Inventory!H2:H1000,"YES") -> 245 | E23: =COUNTIFS(Inventory!D2:D1000,B23,Inventory!H2:H1000,"NO") -> 3 | F23: =SUMIFS(Inventory!E2:E1000,Inventory!D2:D1000,B23,Inventory!H2:H1000,"NO") -> 7976 | G23: =C23+E23 -> 4 | H23: =D23+F23 -> 8221 | I23: =IF(G23=0,"",C23/G23) -> 0.25 | J23: =IF(H23=0,"",D23/H23) -> 0.029801727 | L23: =COUNTIFS(Inventory!D2:D1000,B23,Inventory!I2:I1000,"Not Retired") -> 4 | M23: =SUMIFS(Inventory!E2:E1000,Inventory!D2:D1000,B23,Inventory!I2:I1000,"Not Retired") -> 8221 | N23: =COUNTIFS(Inventory!D2:D1000,B23,Inventory!I2:I1000,"Retired") -> 0 | O23: =SUMIFS(Inventory!E2:E1000,Inventory!D2:D1000,B23,Inventory!I2:I1000,"Retired") -> 0
B24: Pokemon | C24: =COUNTIFS(Inventory!D2:D1000,B24,Inventory!H2:H1000,"YES") -> 0 | D24: =SUMIFS(Inventory!E2:E1000,Inventory!D2:D1000,B24,Inventory!H2:H1000,"YES") -> 0 | E24: =COUNTIFS(Inventory!D2:D1000,B24,Inventory!H2:H1000,"NO") -> 2 | F24: =SUMIFS(Inventory!E2:E1000,Inventory!D2:D1000,B24,Inventory!H2:H1000,"NO") -> 2637 | G24: =C24+E24 -> 2 | H24: =D24+F24 -> 2637 | I24: =IF(G24=0,"",C24/G24) -> 0 | J24: =IF(H24=0,"",D24/H24) -> 0 | L24: =COUNTIFS(Inventory!D2:D1000,B24,Inventory!I2:I1000,"Not Retired") -> 2 | M24: =SUMIFS(Inventory!E2:E1000,Inventory!D2:D1000,B24,Inventory!I2:I1000,"Not Retired") -> 2637 | N24: =COUNTIFS(Inventory!D2:D1000,B24,Inventory!I2:I1000,"Retired") -> 0 | O24: =SUMIFS(Inventory!E2:E1000,Inventory!D2:D1000,B24,Inventory!I2:I1000,"Retired") -> 0
B25: Disney | C25: =COUNTIFS(Inventory!D2:D1000,B25,Inventory!H2:H1000,"YES") -> 0 | D25: =SUMIFS(Inventory!E2:E1000,Inventory!D2:D1000,B25,Inventory!H2:H1000,"YES") -> 0 | E25: =COUNTIFS(Inventory!D2:D1000,B25,Inventory!H2:H1000,"NO") -> 1 | F25: =SUMIFS(Inventory!E2:E1000,Inventory!D2:D1000,B25,Inventory!H2:H1000,"NO") -> 811 | G25: =C25+E25 -> 1 | H25: =D25+F25 -> 811 | I25: =IF(G25=0,"",C25/G25) -> 0 | J25: =IF(H25=0,"",D25/H25) -> 0 | L25: =COUNTIFS(Inventory!D2:D1000,B25,Inventory!I2:I1000,"Not Retired") -> 1 | M25: =SUMIFS(Inventory!E2:E1000,Inventory!D2:D1000,B25,Inventory!I2:I1000,"Not Retired") -> 811 | N25: =COUNTIFS(Inventory!D2:D1000,B25,Inventory!I2:I1000,"Retired") -> 0 | O25: =SUMIFS(Inventory!E2:E1000,Inventory!D2:D1000,B25,Inventory!I2:I1000,"Retired") -> 0
B26: Jurassic World | C26: =COUNTIFS(Inventory!D2:D1000,B26,Inventory!H2:H1000,"YES") -> 1 | D26: =SUMIFS(Inventory!E2:E1000,Inventory!D2:D1000,B26,Inventory!H2:H1000,"YES") -> 3145 | E26: =COUNTIFS(Inventory!D2:D1000,B26,Inventory!H2:H1000,"NO") -> 0 | F26: =SUMIFS(Inventory!E2:E1000,Inventory!D2:D1000,B26,Inventory!H2:H1000,"NO") -> 0 | G26: =C26+E26 -> 1 | H26: =D26+F26 -> 3145 | I26: =IF(G26=0,"",C26/G26) -> 1 | J26: =IF(H26=0,"",D26/H26) -> 1 | L26: =COUNTIFS(Inventory!D2:D1000,B26,Inventory!I2:I1000,"Not Retired") -> 1 | M26: =SUMIFS(Inventory!E2:E1000,Inventory!D2:D1000,B26,Inventory!I2:I1000,"Not Retired") -> 3145 | N26: =COUNTIFS(Inventory!D2:D1000,B26,Inventory!I2:I1000,"Retired") -> 0 | O26: =SUMIFS(Inventory!E2:E1000,Inventory!D2:D1000,B26,Inventory!I2:I1000,"Retired") -> 0
B27: Botanical Collection | C27: =COUNTIFS(Inventory!D2:D1000,B27,Inventory!H2:H1000,"YES") -> 1 | D27: =SUMIFS(Inventory!E2:E1000,Inventory!D2:D1000,B27,Inventory!H2:H1000,"YES") -> 878 | E27: =COUNTIFS(Inventory!D2:D1000,B27,Inventory!H2:H1000,"NO") -> 0 | F27: =SUMIFS(Inventory!E2:E1000,Inventory!D2:D1000,B27,Inventory!H2:H1000,"NO") -> 0 | G27: =C27+E27 -> 1 | H27: =D27+F27 -> 878 | I27: =IF(G27=0,"",C27/G27) -> 1 | J27: =IF(H27=0,"",D27/H27) -> 1 | L27: =COUNTIFS(Inventory!D2:D1000,B27,Inventory!I2:I1000,"Not Retired") -> 1 | M27: =SUMIFS(Inventory!E2:E1000,Inventory!D2:D1000,B27,Inventory!I2:I1000,"Not Retired") -> 878 | N27: =COUNTIFS(Inventory!D2:D1000,B27,Inventory!I2:I1000,"Retired") -> 0 | O27: =SUMIFS(Inventory!E2:E1000,Inventory!D2:D1000,B27,Inventory!I2:I1000,"Retired") -> 0
B28: Harry Potter | C28: =COUNTIFS(Inventory!D2:D1000,B28,Inventory!H2:H1000,"YES") -> 1 | D28: =SUMIFS(Inventory!E2:E1000,Inventory!D2:D1000,B28,Inventory!H2:H1000,"YES") -> 403 | E28: =COUNTIFS(Inventory!D2:D1000,B28,Inventory!H2:H1000,"NO") -> 0 | F28: =SUMIFS(Inventory!E2:E1000,Inventory!D2:D1000,B28,Inventory!H2:H1000,"NO") -> 0 | G28: =C28+E28 -> 1 | H28: =D28+F28 -> 403 | I28: =IF(G28=0,"",C28/G28) -> 1 | J28: =IF(H28=0,"",D28/H28) -> 1 | L28: =COUNTIFS(Inventory!D2:D1000,B28,Inventory!I2:I1000,"Not Retired") -> 0 | M28: =SUMIFS(Inventory!E2:E1000,Inventory!D2:D1000,B28,Inventory!I2:I1000,"Not Retired") -> 0 | N28: =COUNTIFS(Inventory!D2:D1000,B28,Inventory!I2:I1000,"Retired") -> 1 | O28: =SUMIFS(Inventory!E2:E1000,Inventory!D2:D1000,B28,Inventory!I2:I1000,"Retired") -> 403
B29: Creator | C29: =COUNTIFS(Inventory!D2:D1000,B29,Inventory!H2:H1000,"YES") -> 0 | D29: =SUMIFS(Inventory!E2:E1000,Inventory!D2:D1000,B29,Inventory!H2:H1000,"YES") -> 0 | E29: =COUNTIFS(Inventory!D2:D1000,B29,Inventory!H2:H1000,"NO") -> 1 | F29: =SUMIFS(Inventory!E2:E1000,Inventory!D2:D1000,B29,Inventory!H2:H1000,"NO") -> 336 | G29: =C29+E29 -> 1 | H29: =D29+F29 -> 336 | I29: =IF(G29=0,"",C29/G29) -> 0 | J29: =IF(H29=0,"",D29/H29) -> 0 | L29: =COUNTIFS(Inventory!D2:D1000,B29,Inventory!I2:I1000,"Not Retired") -> 1 | M29: =SUMIFS(Inventory!E2:E1000,Inventory!D2:D1000,B29,Inventory!I2:I1000,"Not Retired") -> 336 | N29: =COUNTIFS(Inventory!D2:D1000,B29,Inventory!I2:I1000,"Retired") -> 0 | O29: =SUMIFS(Inventory!E2:E1000,Inventory!D2:D1000,B29,Inventory!I2:I1000,"Retired") -> 0
B30: DC | C30: =COUNTIFS(Inventory!D3:D1001,B30,Inventory!H3:H1001,"YES") -> 0 | D30: =SUMIFS(Inventory!E3:E1001,Inventory!D3:D1001,B30,Inventory!H3:H1001,"YES") -> 0 | E30: =COUNTIFS(Inventory!D3:D1001,B30,Inventory!H3:H1001,"NO") -> 1 | F30: =SUMIFS(Inventory!E3:E1001,Inventory!D3:D1001,B30,Inventory!H3:H1001,"NO") -> 422 | G30: =C30+E30 -> 1 | H30: =D30+F30 -> 422 | I30: =IF(G30=0,"",C30/G30) -> 0 | J30: =IF(H30=0,"",D30/H30) -> 0 | L30: =COUNTIFS(Inventory!D3:D1001,B30,Inventory!I3:I1001,"Not Retired") -> 0 | M30: =SUMIFS(Inventory!E3:E1001,Inventory!D3:D1001,B30,Inventory!I3:I1001,"Not Retired") -> 0 | N30: =COUNTIFS(Inventory!D3:D1001,B30,Inventory!I3:I1001,"Retired") -> 1 | O30: =SUMIFS(Inventory!E3:E1001,Inventory!D3:D1001,B30,Inventory!I3:I1001,"Retired") -> 422
B31: TOTAL | C31: =SUM(C13:C30) -> 66 | D31: =SUM(D13:D30) -> 76040 | E31: =SUM(E13:E30) -> 72 | F31: =SUM(F13:F30) -> 105426 | G31: =SUM(G13:G30) -> 138 | H31: =SUM(H13:H30) -> 181466 | I31: =IF(G31=0,"",C31/G31) -> 0.47826087 | J31: =IF(H31=0,"",D31/H31) -> 0.41903166 | L31: =SUM(L13:L30) -> 75 | M31: =SUM(M13:M30) -> 114690 | N31: =SUM(N13:N30) -> 63 | O31: =SUM(O13:O30) -> 66776
B33: RETIREMENT BY YEAR | F33: COLLECTION OVERVIEW MATRIX
B34: Year | C34: Sets | D34: Bricks | G34: Not Retired | I34: Retired | K34: Total
B35: 2011 | C35: =COUNTIF(Inventory!G2:G1000,B35) -> 1 | D35: =SUMIF(Inventory!G2:G1000,B35,Inventory!E2:E1000) -> 560 | G35: Sets | H35: Bricks | I35: Sets | J35: Bricks | K35: Sets | M35: Bricks
B36: 2012 | C36: =COUNTIF(Inventory!G2:G1000,B36) -> 1 | D36: =SUMIF(Inventory!G2:G1000,B36,Inventory!E2:E1000) -> 4287 | F36: To Build | G36: =COUNTIFS(Inventory!H2:H1000,"NO",Inventory!I2:I1000,"Not Retired") -> 48 | H36: =SUMIFS(Inventory!E2:E1000,Inventory!H2:H1000,"NO",Inventory!I2:I1000,"Not Retired") -> 79302 | I36: =COUNTIFS(Inventory!H2:H1000,"NO",Inventory!I2:I1000,"Retired") -> 24 | J36: =SUMIFS(Inventory!E2:E1000,Inventory!H2:H1000,"NO",Inventory!I2:I1000,"Retired") -> 26124 | K36: =G36+I36 -> 72 | M36: =H36+J36 -> 105426
B37: 2015 | C37: =COUNTIF(Inventory!G2:G1000,B37) -> 2 | D37: =SUMIF(Inventory!G2:G1000,B37,Inventory!E2:E1000) -> 708 | F37: Built | G37: =COUNTIFS(Inventory!H2:H1000,"YES",Inventory!I2:I1000,"Not Retired") -> 27 | H37: =SUMIFS(Inventory!E2:E1000,Inventory!H2:H1000,"YES",Inventory!I2:I1000,"Not Retired") -> 35388 | I37: =COUNTIFS(Inventory!H2:H1000,"YES",Inventory!I2:I1000,"Retired") -> 39 | J37: =SUMIFS(Inventory!E2:E1000,Inventory!H2:H1000,"YES",Inventory!I2:I1000,"Retired") -> 40652 | K37: =G37+I37 -> 66 | M37: =H37+J37 -> 76040
B38: 2016 | C38: =COUNTIF(Inventory!G2:G1000,B38) -> 7 | D38: =SUMIF(Inventory!G2:G1000,B38,Inventory!E2:E1000) -> 4706 | F38: Total | G38: =G36+G37 -> 75 | H38: =H36+H37 -> 114690 | I38: =I36+I37 -> 63 | J38: =J36+J37 -> 66776 | K38: =K36+K37 -> 138 | M38: =M36+M37 -> 181466
B39: 2017 | C39: =COUNTIF(Inventory!G2:G1000,B39) -> 8 | D39: =SUMIF(Inventory!G2:G1000,B39,Inventory!E2:E1000) -> 3175
B40: 2018 | C40: =COUNTIF(Inventory!G2:G1000,B40) -> 4 | D40: =SUMIF(Inventory!G2:G1000,B40,Inventory!E2:E1000) -> 5981
B41: 2021 | C41: =COUNTIF(Inventory!G2:G1000,B41) -> 4 | D41: =SUMIF(Inventory!G2:G1000,B41,Inventory!E2:E1000) -> 2574
B42: 2022 | C42: =COUNTIF(Inventory!G2:G1000,B42) -> 8 | D42: =SUMIF(Inventory!G2:G1000,B42,Inventory!E2:E1000) -> 8591
B43: 2023 | C43: =COUNTIF(Inventory!G2:G1000,B43) -> 5 | D43: =SUMIF(Inventory!G2:G1000,B43,Inventory!E2:E1000) -> 4963
B44: 2024 | C44: =COUNTIF(Inventory!G2:G1000,B44) -> 11 | D44: =SUMIF(Inventory!G2:G1000,B44,Inventory!E2:E1000) -> 17807
B45: 2025 | C45: =COUNTIF(Inventory!G2:G1000,B45) -> 11 | D45: =SUMIF(Inventory!G2:G1000,B45,Inventory!E2:E1000) -> 12937
...

Sheet Inventory
A1: # | B1: Set Number | C1: Set Name | D1: Theme | E1: Pieces | F1: Year Released | G1: Year Retired | H1: Built | I1: Retired
A2: 1 | B2: 21061 | C2: Notre-Dame de Paris | D2: Architecture | E2: 4383 | F2: 2024 | G2: - | H2: NO | I2: =IF(B2="","",IF(G2="-","Not Retired",IF(G2<YEAR(NOW()),"Retired","Not Retired"))) -> Not Retired
A3: =+A2+1 -> 2 | B3: 21063 | C3: Neuschwanstein Castle | D3: Architecture | E3: 3455 | F3: 2025 | G3: - | H3: NO | I3: =IF(B3="","",IF(G3="-","Not Retired",IF(G3<YEAR(NOW()),"Retired","Not Retired"))) -> Not Retired
A4: =+A3+1 -> 3 | B4: 21060 | C4: Himeji Castle | D4: Architecture | E4: 2125 | F4: 2023 | G4: 2026 | H4: NO | I4: =IF(B4="","",IF(G4="-","Not Retired",IF(G4<YEAR(NOW()),"Retired","Not Retired"))) -> Not Retired
A5: =+A4+1 -> 4 | B5: 21042 | C5: Statue of Liberty | D5: Architecture | E5: 1685 | F5: 2018 | G5: 2026 | H5: YES | I5: =IF(B5="","",IF(G5="-","Not Retired",IF(G5<YEAR(NOW()),"Retired","Not Retired"))) -> Not Retired
A6: =+A5+1 -> 5 | B6: 21029 | C6: Buckingham Palace | D6: Architecture | E6: 780 | F6: 2016 | G6: 2018 | H6: YES | I6: =IF(B6="","",IF(G6="-","Not Retired",IF(G6<YEAR(NOW()),"Retired","Not Retired"))) -> Retired
A7: =+A6+1 -> 6 | B7: 21024 | C7: Louvre | D7: Architecture | E7: 695 | F7: 2015 | G7: 2017 | H7: YES | I7: =IF(B7="","",IF(G7="-","Not Retired",IF(G7<YEAR(NOW()),"Retired","Not Retired"))) -> Retired
A8: =+A7+1 -> 7 | B8: 21028 | C8: New York City | D8: Architecture | E8: 598 | F8: 2016 | G8: 2025 | H8: YES | I8: =IF(B8="","",IF(G8="-","Not Retired",IF(G8<YEAR(NOW()),"Retired","Not Retired"))) -> Retired
A9: =+A8+1 -> 8 | B9: 21006 | C9: The White House | D9: Architecture | E9: 560 | F9: 2010 | G9: 2011 | H9: YES | I9: =IF(B9="","",IF(G9="-","Not Retired",IF(G9<YEAR(NOW()),"Retired","Not Retired"))) -> Retired
A10: =+A9+1 -> 9 | B10: 21023 | C10: Flatiron Buildiing | D10: Architecture | E10: 471 | F10: 2015 | G10: 2016 | H10: YES | I10: =IF(B10="","",IF(G10="-","Not Retired",IF(G10<YEAR(NOW()),"Retired","Not Retired"))) -> Retired
A11: =+A10+1 -> 10 | B11: 21034 | C11: London | D11: Architecture | E11: 468 | F11: 2017 | G11: - | H11: NO | I11: =IF(B11="","",IF(G11="-","Not Retired",IF(G11<YEAR(NOW()),"Retired","Not Retired"))) -> Not Retired
A12: =+A11+1 -> 11 | B12: 21011 | C12: Brandenburg Gate | D12: Architecture | E12: 363 | F12: 2011 | G12: 2015 | H12: YES | I12: =IF(B12="","",IF(G12="-","Not Retired",IF(G12<YEAR(NOW()),"Retired","Not Retired"))) -> Retired
A13: =+A12+1 -> 12 | B13: 21013 | C13: Big Ben | D13: Architecture | E13: 346 | F13: 2012 | G13: 2016 | H13: YES | I13: =IF(B13="","",IF(G13="-","Not Retired",IF(G13<YEAR(NOW()),"Retired","Not Retired"))) -> Retired
A14: =+A13+1 -> 13 | B14: 21015 | C14: The Leaning Tower of Pisa | D14: Architecture | E14: 345 | F14: 2013 | G14: 2015 | H14: YES | I14: =IF(B14="","",IF(G14="-","Not Retired",IF(G14<YEAR(NOW()),"Retired","Not Retired"))) -> Retired
A15: =+A14+1 -> 14 | B15: 21055 | C15: Burj Khalifa | D15: Architecture | E15: 333 | F15: 2019 | G15: 2022 | H15: YES | I15: =IF(B15="","",IF(G15="-","Not Retired",IF(G15<YEAR(NOW()),"Retired","Not Retired"))) -> Retired
A16: =+A15+1 -> 15 | B16: 21019 | C16: The Iiffel Tower | D16: Architecture | E16: 321 | F16: 2014 | G16: 2018 | H16: YES | I16: =IF(B16="","",IF(G16="-","Not Retired",IF(G16<YEAR(NOW()),"Retired","Not Retired"))) -> Retired
A17: =+A16+1 -> 16 | B17: 21027 | C17: Berlin | D17: Architecture | E17: 289 | F17: 2016 | G17: 2017 | H17: YES | I17: =IF(B17="","",IF(G17="-","Not Retired",IF(G17<YEAR(NOW()),"Retired","Not Retired"))) -> Retired
A18: =+A17+1 -> 17 | B18: 21022 | C18: Lincoln Memorial | D18: Architecture | E18: 274 | F18: 2015 | G18: 2016 | H18: YES | I18: =IF(B18="","",IF(G18="-","Not Retired",IF(G18<YEAR(NOW()),"Retired","Not Retired"))) -> Retired
A19: =+A18+1 -> 18 | B19: 21026 | C19: Venice | D19: Architecture | E19: 212 | F19: 2016 | G19: 2017 | H19: YES | I19: =IF(B19="","",IF(G19="-","Not Retired",IF(G19<YEAR(NOW()),"Retired","Not Retired"))) -> Retired
A20: =+A19+1 -> 19 | B20: 10281 | C20: Bonsai Tree | D20: Botanical Collection | E20: 878 | F20: 2021 | G20: - | H20: YES | I20: =IF(B20="","",IF(G20="-","Not Retired",IF(G20<YEAR(NOW()),"Retired","Not Retired"))) -> Not Retired
A21: =+A20+1 -> 20 | B21: 31382 | C21: Playful Puppy Dog | D21: Creator | E21: 336 | F21: 2026 | G21: - | H21: NO | I21: =IF(B21="","",IF(G21="-","Not Retired",IF(G21<YEAR(NOW()),"Retired","Not Retired"))) -> Not Retired
A22: =+A21+1 -> 21 | B22: 10214 | C22: Tower Bridge | D22: Creator Expert | E22: 4287 | F22: 2010 | G22: 2012 | H22: YES | I22: =IF(B22="","",IF(G22="-","Not Retired",IF(G22<YEAR(NOW()),"Retired","Not Retired"))) -> Retired
A23: =+A22+1 -> 22 | B23: 10253 | C23: Big Ben | D23: Creator Expert | E23: 4163 | F23: 2016 | G23: 2018 | H23: YES | I23: =IF(B23="","",IF(G23="-","Not Retired",IF(G23<YEAR(NOW()),"Retired","Not Retired"))) -> Retired
A24: =+A23+1 -> 23 | B24: 10234 | C24: Sydney Opera House | D24: Creator Expert | E24: 2989 | F24: 2013 | G24: 2016 | H24: YES | I24: =IF(B24="","",IF(G24="-","Not Retired",IF(G24<YEAR(NOW()),"Retired","Not Retired"))) -> Retired
A25: =+A24+1 -> 24 | B25: 10307 | C25: The Eiffel Tower | D25: Icons | E25: 10001 | F25: 2022 | G25: 2026 | H25: NO | I25: =IF(B25="","",IF(G25="-","Not Retired",IF(G25<YEAR(NOW()),"Retired","Not Retired"))) -> Not Retired
A26: =+A25+1 -> 25 | B26: 10294 | C26: Titanic | D26: Icons | E26: 9090 | F26: 2021 | G26: - | H26: YES | I26: =IF(B26="","",IF(G26="-","Not Retired",IF(G26<YEAR(NOW()),"Retired","Not Retired"))) -> Not Retired
A27: =+A26+1 -> 26 | B27: 10335 | C27: The Endurance | D27: Icons | E27: 3011 | F27: 2024 | G27: 2026 | H27: NO | I27: =IF(B27="","",IF(G27="-","Not Retired",IF(G27<YEAR(NOW()),"Retired","Not Retired"))) -> Not Retired
A28: =+A27+1 -> 27 | B28: 10317 | C28: Land Rover Classic Defender 90 | D28: Icons | E28: 2336 | F28: 2023 | G28: 2025 | H28: YES | I28: =IF(B28="","",IF(G28="-","Not Retired",IF(G28<YEAR(NOW()),"Retired","Not Retired"))) -> Retired
A29: =+A28+1 -> 28 | B29: 11384 | C29: Golden Retreiver Puppy | D29: Icons | E29: 2102 | F29: 2026 | G29: - | H29: NO | I29: =IF(B29="","",IF(G29="-","Not Retired",IF(G29<YEAR(NOW()),"Retired","Not Retired"))) -> Not Retired
A30: =+A29+1 -> 29 | B30: 10318 | C30: Concorde | D30: Icons | E30: 2083 | F30: 2023 | G30: 2026 | H30: YES | I30: =IF(B30="","",IF(G30="-","Not Retired",IF(G30<YEAR(NOW()),"Retired","Not Retired"))) -> Not Retired
A31: =+A30+1 -> 30 | B31: 10292 | C31: The Friends Apartment | D31: Icons | E31: 2048 | F31: 2021 | G31: 2023 | H31: YES | I31: =IF(B31="","",IF(G31="-","Not Retired",IF(G31<YEAR(NOW()),"Retired","Not Retired"))) -> Retired
A32: =+A31+1 -> 31 | B32: 10300 | C32: Back to the Future Time Machine | D32: Icons | E32: 1872 | F32: 2022 | G32: 2026 | H32: NO | I32: =IF(B32="","",IF(G32="-","Not Retired",IF(G32<YEAR(NOW()),"Retired","Not Retired"))) -> Not Retired
A33: =+A32+1 -> 32 | B33: 10334 | C33: Retro Radio | D33: Icons | E33: 906 | F33: 2024 | G33: 2026 | H33: NO | I33: =IF(B33="","",IF(G33="-","Not Retired",IF(G33<YEAR(NOW()),"Retired","Not Retired"))) -> Not Retired
A34: =+A33+1 -> 33 | B34: 10353 | C34: Williams Racing FW14B & Nigel Mansel | D34: Icons | E34: 799 | F34: 2025 | G34: - | H34: YES | I34: =IF(B34="","",IF(G34="-","Not Retired",IF(G34<YEAR(NOW()),"Retired","Not Retired"))) -> Not Retired
A35: =+A34+1 -> 34 | B35: 10330 | C35: McLaren MP4/4 & Ayrton Senna | D35: Icons | E35: 693 | F35: 2024 | G35: - | H35: YES | I35: =IF(B35="","",IF(G35="-","Not Retired",IF(G35<YEAR(NOW()),"Retired","Not Retired"))) -> Not Retired
A36: =+A35+1 -> 35 | B36: 21327 | C36: Typewriter | D36: Ideas | E36: 2079 | F36: 2021 | G36: 2024 | H36: YES | I36: =IF(B36="","",IF(G36="-","Not Retired",IF(G36<YEAR(NOW()),"Retired","Not Retired"))) -> Retired
A37: =+A36+1 -> 36 | B37: 21349 | C37: Tuxedo Cat | D37: Ideas | E37: 1710 | F37: 2024 | G37: - | H37: YES | I37: =IF(B37="","",IF(G37="-","Not Retired",IF(G37<YEAR(NOW()),"Retired","Not Retired"))) -> Not Retired
A38: =+A37+1 -> 37 | B38: 21347 | C38: Red London Telephone Box | D38: Ideas | E38: 1460 | F38: 2024 | G38: 2025 | H38: YES | I38: =IF(B38="","",IF(G38="-","Not Retired",IF(G38<YEAR(NOW()),"Retired","Not Retired"))) -> Retired
A39: =+A38+1 -> 38 | B39: 21328 | C39: Seinfeld | D39: Ideas | E39: 1326 | F39: 2021 | G39: 2022 | H39: YES | I39: =IF(B39="","",IF(G39="-","Not Retired",IF(G39<YEAR(NOW()),"Retired","Not Retired"))) -> Retired
A40: =+A39+1 -> 39 | B40: 21361 | C40: Gremlins: Gizmo | D40: Ideas | E40: 1125 | F40: 2025 | G40: - | H40: NO | I40: =IF(B40="","",IF(G40="-","Not Retired",IF(G40<YEAR(NOW()),"Retired","Not Retired"))) -> Not Retired
...

Sheet Totals
A1: TOTAL SETS - Built or Not | E1: TOTAL SETS - Retirement | I1: TOTAL SETS - Retirement by year
B2: Values | E2: Retired | F2: (All) | J2: Values
A3: Row Labels | B3: Sets | C3: Bricks | E3: Built | F3: (All) | I3: Row Labels | J3: Sets | K3: Bricks
A4: NO | B4: 56 | C4: 91571 | I4: 2011 | J4: 1 | K4: 561
A5: Architecture | B5: 6 | C5: 13787 | F5: Values | I5: 2012 | J5: 1 | K5: 4287
A6: Creator | B6: 1 | C6: 336 | E6: Row Labels | F6: Sets | G6: Bricks | I6: 2015 | J6: 2 | K6: 708
A7: Icons | B7: 8 | C7: 22669 | E7: Architecture | F7: 20 | G7: 21060 | I7: 2016 | J7: 7 | K7: 4706
A8: Ideas | B8: 2 | C8: 2880 | E8: Botanical Collection | F8: 1 | G8: 878 | I8: 2017 | J8: 7 | K8: 2849
A9: Jurassic World | B9: 1 | C9: 3145 | E9: Creator | F9: 1 | G9: 336 | I9: 2018 | J9: 4 | K9: 5981
A10: Marvel | B10: 3 | C10: 2299 | E10: Creator Expert | F10: 3 | G10: 11439 | I10: 2021 | J10: 3 | K10: 1834
A11: Other | B11: 4 | C11: 8421 | E11: Icons | F11: 15 | G11: 39177 | I11: 2022 | J11: 8 | K11: 8591
A12: Speed Champions | B12: 3 | C12: 786 | E12: Ideas | F12: 8 | G12: 11138 | I12: 2023 | J12: 4 | K12: 4491
A13: Star Wars | B13: 19 | C13: 22983 | E13: Jurassic World | F13: 1 | G13: 3145 | I13: 2024 | J13: 5 | K13: 8148
A14: Super Mario | B14: 4 | C14: 7553 | E14: Marvel | F14: 3 | G14: 2299 | I14: 2025 | J14: 7 | K14: 9004
A15: Editions | B15: 1 | C15: 2842 | E15: Other | F15: 4 | G15: 8421 | I15: 2026 | J15: 22 | K15: 44719
A16: Pokemon | B16: 2 | C16: 2637 | E16: Speed Champions | F16: 7 | G16: 2065 | I16: - | J16: 40 | K16: 57966
A17: Disney | B17: 1 | C17: 811 | E17: Star Wars | F17: 34 | G17: 34264 | I17: Grand Total | J17: 111 | K17: 153845
A18: DC | B18: 1 | C18: 422 | E18: Super Mario | F18: 5 | G18: 7974
A19: YES | B19: 55 | C19: 62274 | E19: Technic | F19: 2 | G19: 3036
A20: Architecture | B20: 14 | C20: 7273 | E20: Editions | F20: 2 | G20: 4340
A21: Botanical Collection | B21: 1 | C21: 878 | E21: Pokemon | F21: 2 | G21: 2637
A22: Creator Expert | B22: 3 | C22: 11439 | E22: Harry Potter | F22: 1 | G22: 403
A23: Icons | B23: 7 | C23: 16508 | E23: Disney | F23: 1 | G23: 811
A24: Ideas | B24: 6 | C24: 8258 | E24: DC | F24: 1 | G24: 422
A25: Speed Champions | B25: 4 | C25: 1279 | E25: Grand Total | F25: 111 | G25: 153845
A26: Star Wars | B26: 15 | C26: 11281
A27: Super Mario | B27: 1 | C27: 421
A28: Technic | B28: 2 | C28: 3036
A29: Editions | B29: 1 | C29: 1498
A30: Harry Potter | B30: 1 | C30: 403
A31: Grand Total | B31: 111 | C31: 153845

Sheet Settings
A1: Last Update | B1: 46190
A2: Version | B2: 4
